Workbook

Sheet Raw Sales Data
A1: Order ID | B1: Order Date | C1: Customer | D1: Product | E1: Category | F1: Region | G1: Quantity | H1: Discount | I1: Sales | J1: Profit
A2: ORD-00001 | B2: 45985 | C2: Customer 018 | D2: Wireless Mouse | E2: Technology | F2: North | G2: 1 | H2: 0.1 | I2: 31.5 | J2: 11.63
A3: ORD-00002 | B3: 46004 | C3: Customer 005 | D3: Coffee Table | E3: Furniture | F3: North | G3: 5 | H3: 0 | I3: 1050 | J3: 267.89
A4: ORD-00003 | B4: 45705 | C4: Customer 072 | D4: Desk Lamp | E4: Furniture | F4: South | G4: 2 | H4: 0.2 | I4: 88 | J4: 22.12
A5: ORD-00004 | B5: 45990 | C5: Customer 076 | D5: Coffee Table | E5: Furniture | F5: East | G5: 5 | H5: 0.15 | I5: 892.5 | J5: 336.7
A6: ORD-00005 | B6: 45661 | C6: Customer 028 | D6: Office Chair | E6: Furniture | F6: East | G6: 4 | H6: 0.1 | I6: 1008 | J6: 361.17
A7: ORD-00006 | B7: 45710 | C7: Customer 045 | D7: Wireless Mouse | E7: Technology | F7: East | G7: 4 | H7: 0 | I7: 140 | J7: 46.42
A8: ORD-00007 | B8: 45680 | C8: Customer 049 | D8: Coffee Table | E8: Furniture | F8: North | G8: 4 | H8: 0.2 | I8: 672 | J8: 274.72
A9: ORD-00008 | B9: 45940 | C9: Customer 091 | D9: Smartphone X | E9: Technology | F9: North | G9: 5 | H9: 0.1 | I9: 3825 | J9: 992.49
A10: ORD-00009 | B10: 45681 | C10: Customer 030 | D10: Monitor 24 | E10: Technology | F10: North | G10: 2 | H10: 0.1 | I10: 576 | J10: 71.93
A11: ORD-00010 | B11: 45852 | C11: Customer 046 | D11: Smartphone X | E11: Technology | F11: South | G11: 4 | H11: 0.1 | I11: 3060 | J11: 1212.75
A12: ORD-00011 | B12: 46001 | C12: Customer 069 | D12: Smartphone X | E12: Technology | F12: South | G12: 1 | H12: 0.2 | I12: 680 | J12: 163.51
A13: ORD-00012 | B13: 45741 | C13: Customer 082 | D13: Notebook Pack | E13: Office Supplies | F13: South | G13: 4 | H13: 0.1 | I13: 64.8 | J13: 8
... A232: ORD-00231 | B232: 45844 | C232: Customer 044 | D232: Keyboard | E232: Technology | F232: North | G232: 3 | H232: 0.15 | I232: 178.5 | J232: 56.25
A233: ORD-00232 | B233: 45981 | D233: Monitor 24 | E233: Technology | F233: West | G233: 3 | H233: 0 | I233: 960 | J233: 327.55
A234: ORD-00233 | B234: 45803 | C234: Customer 075 | D234: Smartphone X | E234: Technology | F234: South | G234: 5 | H234: 0.05 | I234: 4037.5 | J234: 1372.71
A235: ORD-00234 | B235: 45837 | C235: Customer 011 | D235: Smartphone X | E235: Technology | F235: East | G235: 4 | H235: 0.05 | I235: 3230 | J235: 819.25
A236: ORD-00235 | B236: 45944 | C236: Customer 095 | D236: Bookshelf | E236: Furniture | F236: North | G236: 3 | H236: 0.05 | I236: 541.5 | J236: 123.93
A237: ORD-00236 | B237: 45988 | C237: Customer 047 | D237: Monitor 24 | E237: Technology | F237: East | G237: 4 | H237: 0.2 | I237: 1024 | J237: 338.53
A238: ORD-00237 | B238: 45750 | C238: Customer 018 | D238: Desk Lamp | E238: Furniture | F238: South | G238: 3 | H238: 0.15 | I238: 140.25 | J238: 54.23
A239: ORD-00238 | B239: 45697 | C239: Customer 095 | D239: Smartphone X | E239: Technology | F239: North | G239: 1 | H239: 0.2 | I239: 680 | J239: 133.02
A240: ORD-00239 | B240: 45996 | C240: Customer 020 | D240: Keyboard | E240: Technology | F240: South | G240: 5 | H240: 0.05 | I240: 332.5 | J240: 84.09
A241: ORD-00240 | B241: 45750 | C241: Customer 006 | D241: Coffee Table | E241: Furniture | F241: West | G241: 5 | H241: 0.05 | I241: 997.5 | J241: 211.48
A242: ORD-00241 | B242: 45844 | C242: Customer 097 | D242: Monitor 24 | E242: Technology | F242: West | G242: 2 | H242: 0.15 | I242: 544 | J242: 135.19
A243: ORD-00242 | B243: 45777 | C243: Customer 061 | D243: Printer | E243: Office Supplies | F243: South | G243: 2 | H243: 0.1 | I243: 432 | J243: 56.74
A244: ORD-00243 | B244: 45846 | C244: Customer 037 | D244: Monitor 24 | E244: Technology | F244: West | G244: 5 | H244: 0.15 | I244: 1360 | J244: 404.8
A245: ORD-00244 | B245: 45915 | C245: Customer 078 | D245: Printer | E245: Office Supplies | F245: South | G245: 4 | H245: 0.05 | I245: 912 | J245: 164.55
... A413: ORD-00412 | B413: 45995 | C413: Customer 077 | D413: Office Chair | E413: Furniture | F413: West | G413: 4 | H413: 0.15 | I413: 952 | J413: 405.16
A414: ORD-00413 | B414: 45956 | C414: Customer 089 | D414: Bookshelf | E414: Furniture | F414: West | G414: 5 | I414: 760 | J414: 110.39
A415: ORD-00414 | B415: 45936 | C415: Customer 011 | D415: Laptop Pro 15 | E415: Technology | F415: North | G415: 3 | H415: 0.2 | I415: 2880 | J415: 731.63
A416: ORD-00415 | B416: 45785 | C416: Customer 006 | D416: Monitor 24 | E416: Technology | F416: West | G416: 3 | H416: 0.05 | I416: 912 | J416: 215.68
A417: ORD-00416 | B417: 45827 | C417: Customer 029 | D417: Bookshelf | E417: Furniture | F417: South | G417: 1 | H417: 0 | I417: 190 | J417: 79.32
A418: ORD-00417 | B418: 45886 | C418: Customer 076 | D418: Keyboard | E418: Technology | F418: South | G418: 4 | H418: 0.15 | I418: 238 | J418: 46.44
A419: ORD-00418 | B419: 45834 | C419: Customer 011 | D419: Laptop Pro 15 | E419: Technology | F419: North | G419: 4 | H419: 0 | I419: 4800 | J419: 1692.04
A420: ORD-00419 | B420: 45730 | C420: Customer 027 | D420: Keyboard | E420: Technology | F420: West | G420: 3 | H420: 0.1 | I420: 189 | J420: 56.65
A421: ORD-00420 | B421: 45836 | C421: Customer 058 | D421: Notebook Pack | E421: Office Supplies | F421: East | G421: 1 | H421: 0.15 | I421: 15.3 | J421: 3.24
A422: ORD-00421 | B422: 45692 | C422: Customer 044 | D422: Smartphone X | E422: Technology | F422: North | G422: 1 | H422: 0 | I422: 850 | J422: 376.16
A423: ORD-00422 | B423: 46004 | C423: Customer 021 | D423: Office Chair | E423: Furniture | F423: East | G423: 2 | H423: 0.2 | I423: 448 | J423: 175.81
A424: ORD-00423 | B424: 45944 | C424: Customer 081 | D424: Bookshelf | E424: Furniture | F424: South | G424: 4 | H424: 0.05 | I424: 722 | J424: 134.83
A425: ORD-00424 | B425: 45753 | C425: Customer 079 | D425: Monitor 24 | E425: Technology | F425: South | G425: 4 | H425: 0.15 | I425: 1088 | J425: 479.12
...

Sheet Clean Sales Data
A1: Order ID | B1: Order Date | C1: Customer | D1: Product | E1: Category 1 | F1: Region | G1: Quantity | H1: Discount | I1: Sales | J1: Profit | K1: Category | L1: Month | M1: Month Sort
A2: ORD-00001 | B2: 45985 | C2: Customer 018 | D2: Wireless Mouse | E2: Technology | F2: North | G2: 1 | H2: 0.1 | I2: 31.5 | J2: 11.63 | K2: =TRIM(E2) -> Technology | L2: =TEXT(B2,"mmm-yyyy") -> Nov-2025 | M2: =DATE(YEAR(B2),MONTH(B2),1) -> 45962
A3: ORD-00002 | B3: 46004 | C3: Customer 005 | D3: Coffee Table | E3: Furniture | F3: North | G3: 5 | H3: 0 | I3: 1050 | J3: 267.89 | K3: =TRIM(E3) -> Furniture | L3: =TEXT(B3,"mmm-yyyy") -> Dec-2025 | M3: =DATE(YEAR(B3),MONTH(B3),1) -> 45992
A4: ORD-00003 | B4: 45705 | C4: Customer 072 | D4: Desk Lamp | E4: Furniture | F4: South | G4: 2 | H4: 0.2 | I4: 88 | J4: 22.12 | K4: =TRIM(E4) -> Furniture | L4: =TEXT(B4,"mmm-yyyy") -> Feb-2025 | M4: =DATE(YEAR(B4),MONTH(B4),1) -> 45689
A5: ORD-00004 | B5: 45990 | C5: Customer 076 | D5: Coffee Table | E5: Furniture | F5: East | G5: 5 | H5: 0.15 | I5: 892.5 | J5: 336.7 | K5: =TRIM(E5) -> Furniture | L5: =TEXT(B5,"mmm-yyyy") -> Nov-2025 | M5: =DATE(YEAR(B5),MONTH(B5),1) -> 45962
A6: ORD-00005 | B6: 45661 | C6: Customer 028 | D6: Office Chair | E6: Furniture | F6: East | G6: 4 | H6: 0.1 | I6: 1008 | J6: 361.17 | K6: =TRIM(E6) -> Furniture | L6: =TEXT(B6,"mmm-yyyy") -> Jan-2025 | M6: =DATE(YEAR(B6),MONTH(B6),1) -> 45658
A7: ORD-00006 | B7: 45710 | C7: Customer 045 | D7: Wireless Mouse | E7: Technology | F7: East | G7: 4 | H7: 0 | I7: 140 | J7: 46.42 | K7: =TRIM(E7) -> Technology | L7: =TEXT(B7,"mmm-yyyy") -> Feb-2025 | M7: =DATE(YEAR(B7),MONTH(B7),1) -> 45689
A8: ORD-00007 | B8: 45680 | C8: Customer 049 | D8: Coffee Table | E8: Furniture | F8: North | G8: 4 | H8: 0.2 | I8: 672 | J8: 274.72 | K8: =TRIM(E8) -> Furniture | L8: =TEXT(B8,"mmm-yyyy") -> Jan-2025 | M8: =DATE(YEAR(B8),MONTH(B8),1) -> 45658
A9: ORD-00008 | B9: 45940 | C9: Customer 091 | D9: Smartphone X | E9: Technology | F9: North | G9: 5 | H9: 0.1 | I9: 3825 | J9: 992.49 | K9: =TRIM(E9) -> Technology | L9: =TEXT(B9,"mmm-yyyy") -> Oct-2025 | M9: =DATE(YEAR(B9),MONTH(B9),1) -> 45931
A10: ORD-00009 | B10: 45681 | C10: Customer 030 | D10: Monitor 24 | E10: Technology | F10: North | G10: 2 | H10: 0.1 | I10: 576 | J10: 71.93 | K10: =TRIM(E10) -> Technology | L10: =TEXT(B10,"mmm-yyyy") -> Jan-2025 | M10: =DATE(YEAR(B10),MONTH(B10),1) -> 45658
A11: ORD-00010 | B11: 45852 | C11: Customer 046 | D11: Smartphone X | E11: Technology | F11: South | G11: 4 | H11: 0.1 | I11: 3060 | J11: 1212.75 | K11: =TRIM(E11) -> Technology | L11: =TEXT(B11,"mmm-yyyy") -> Jul-2025 | M11: =DATE(YEAR(B11),MONTH(B11),1) -> 45839
A12: ORD-00011 | B12: 46001 | C12: Customer 069 | D12: Smartphone X | E12: Technology | F12: South | G12: 1 | H12: 0.2 | I12: 680 | J12: 163.51 | K12: =TRIM(E12) -> Technology | L12: =TEXT(B12,"mmm-yyyy") -> Dec-2025 | M12: =DATE(YEAR(B12),MONTH(B12),1) -> 45992
A13: ORD-00012 | B13: 45741 | C13: Customer 082 | D13: Notebook Pack | E13: Office Supplies | F13: South | G13: 4 | H13: 0.1 | I13: 64.8 | J13: 8 | K13: =TRIM(E13) -> Office Supplies | L13: =TEXT(B13,"mmm-yyyy") -> Mar-2025 | M13: =DATE(YEAR(B13),MONTH(B13),1) -> 45717
... A232: ORD-00231 | B232: 45844 | C232: Customer 044 | D232: Keyboard | E232: Technology | F232: North | G232: 3 | H232: 0.15 | I232: 178.5 | J232: 56.25 | K232: =TRIM(E232) -> Technology | L232: =TEXT(B232,"mmm-yyyy") -> Jul-2025 | M232: =DATE(YEAR(B232),MONTH(B232),1) -> 45839
A233: ORD-00232 | B233: 45981 | D233: Monitor 24 | E233: Technology | F233: West | G233: 3 | H233: 0 | I233: 960 | J233: 327.55 | K233: =TRIM(E233) -> Technology | L233: =TEXT(B233,"mmm-yyyy") -> Nov-2025 | M233: =DATE(YEAR(B233),MONTH(B233),1) -> 45962
A234: ORD-00233 | B234: 45803 | C234: Customer 075 | D234: Smartphone X | E234: Technology | F234: South | G234: 5 | H234: 0.05 | I234: 4037.5 | J234: 1372.71 | K234: =TRIM(E234) -> Technology | L234: =TEXT(B234,"mmm-yyyy") -> May-2025 | M234: =DATE(YEAR(B234),MONTH(B234),1) -> 45778
A235: ORD-00234 | B235: 45837 | C235: Customer 011 | D235: Smartphone X | E235: Technology | F235: East | G235: 4 | H235: 0.05 | I235: 3230 | J235: 819.25 | K235: =TRIM(E235) -> Technology | L235: =TEXT(B235,"mmm-yyyy") -> Jun-2025 | M235: =DATE(YEAR(B235),MONTH(B235),1) -> 45809
A236: ORD-00235 | B236: 45944 | C236: Customer 095 | D236: Bookshelf | E236: Furniture | F236: North | G236: 3 | H236: 0.05 | I236: 541.5 | J236: 123.93 | K236: =TRIM(E236) -> Furniture | L236: =TEXT(B236,"mmm-yyyy") -> Oct-2025 | M236: =DATE(YEAR(B236),MONTH(B236),1) -> 45931
A237: ORD-00236 | B237: 45988 | C237: Customer 047 | D237: Monitor 24 | E237: Technology | F237: East | G237: 4 | H237: 0.2 | I237: 1024 | J237: 338.53 | K237: =TRIM(E237) -> Technology | L237: =TEXT(B237,"mmm-yyyy") -> Nov-2025 | M237: =DATE(YEAR(B237),MONTH(B237),1) -> 45962
A238: ORD-00237 | B238: 45750 | C238: Customer 018 | D238: Desk Lamp | E238: Furniture | F238: South | G238: 3 | H238: 0.15 | I238: 140.25 | J238: 54.23 | K238: =TRIM(E238) -> Furniture | L238: =TEXT(B238,"mmm-yyyy") -> Apr-2025 | M238: =DATE(YEAR(B238),MONTH(B238),1) -> 45748
A239: ORD-00238 | B239: 45697 | C239: Customer 095 | D239: Smartphone X | E239: Technology | F239: North | G239: 1 | H239: 0.2 | I239: 680 | J239: 133.02 | K239: =TRIM(E239) -> Technology | L239: =TEXT(B239,"mmm-yyyy") -> Feb-2025 | M239: =DATE(YEAR(B239),MONTH(B239),1) -> 45689
A240: ORD-00239 | B240: 45996 | C240: Customer 020 | D240: Keyboard | E240: Technology | F240: South | G240: 5 | H240: 0.05 | I240: 332.5 | J240: 84.09 | K240: =TRIM(E240) -> Technology | L240: =TEXT(B240,"mmm-yyyy") -> Dec-2025 | M240: =DATE(YEAR(B240),MONTH(B240),1) -> 45992
A241: ORD-00240 | B241: 45750 | C241: Customer 006 | D241: Coffee Table | E241: Furniture | F241: West | G241: 5 | H241: 0.05 | I241: 997.5 | J241: 211.48 | K241: =TRIM(E241) -> Furniture | L241: =TEXT(B241,"mmm-yyyy") -> Apr-2025 | M241: =DATE(YEAR(B241),MONTH(B241),1) -> 45748
A242: ORD-00241 | B242: 45844 | C242: Customer 097 | D242: Monitor 24 | E242: Technology | F242: West | G242: 2 | H242: 0.15 | I242: 544 | J242: 135.19 | K242: =TRIM(E242) -> Technology | L242: =TEXT(B242,"mmm-yyyy") -> Jul-2025 | M242: =DATE(YEAR(B242),MONTH(B242),1) -> 45839
A243: ORD-00242 | B243: 45777 | C243: Customer 061 | D243: Printer | E243: Office Supplies | F243: South | G243: 2 | H243: 0.1 | I243: 432 | J243: 56.74 | K243: =TRIM(E243) -> Office Supplies | L243: =TEXT(B243,"mmm-yyyy") -> Apr-2025 | M243: =DATE(YEAR(B243),MONTH(B243),1) -> 45748
A244: ORD-00243 | B244: 45846 | C244: Customer 037 | D244: Monitor 24 | E244: Technology | F244: West | G244: 5 | H244: 0.15 | I244: 1360 | J244: 404.8 | K244: =TRIM(E244) -> Technology | L244: =TEXT(B244,"mmm-yyyy") -> Jul-2025 | M244: =DATE(YEAR(B244),MONTH(B244),1) -> 45839
A245: ORD-00244 | B245: 45915 | C245: Customer 078 | D245: Printer | E245: Office Supplies | F245: South | G245: 4 | H245: 0.05 | I245: 912 | J245: 164.55 | K245: =TRIM(E245) -> Office Supplies | L245: =TEXT(B245,"mmm-yyyy") -> Sept-2025 | M245: =DATE(YEAR(B245),MONTH(B245),1) -> 45901
... A413: ORD-00412 | B413: 45995 | C413: Customer 077 | D413: Office Chair | E413: Furniture | F413: West | G413: 4 | H413: 0.15 | I413: 952 | J413: 405.16 | K413: =TRIM(E413) -> Furniture | L413: =TEXT(B413,"mmm-yyyy") -> Dec-2025 | M413: =DATE(YEAR(B413),MONTH(B413),1) -> 45992
A414: ORD-00413 | B414: 45956 | C414: Customer 089 | D414: Bookshelf | E414: Furniture | F414: West | G414: 5 | I414: 760 | J414: 110.39 | K414: =TRIM(E414) -> Furniture | L414: =TEXT(B414,"mmm-yyyy") -> Oct-2025 | M414: =DATE(YEAR(B414),MONTH(B414),1) -> 45931
A415: ORD-00414 | B415: 45936 | C415: Customer 011 | D415: Laptop Pro 15 | E415: Technology | F415: North | G415: 3 | H415: 0.2 | I415: 2880 | J415: 731.63 | K415: =TRIM(E415) -> Technology | L415: =TEXT(B415,"mmm-yyyy") -> Oct-2025 | M415: =DATE(YEAR(B415),MONTH(B415),1) -> 45931
A416: ORD-00415 | B416: 45785 | C416: Customer 006 | D416: Monitor 24 | E416: Technology | F416: West | G416: 3 | H416: 0.05 | I416: 912 | J416: 215.68 | K416: =TRIM(E416) -> Technology | L416: =TEXT(B416,"mmm-yyyy") -> May-2025 | M416: =DATE(YEAR(B416),MONTH(B416),1) -> 45778
A417: ORD-00416 | B417: 45827 | C417: Customer 029 | D417: Bookshelf | E417: Furniture | F417: South | G417: 1 | H417: 0 | I417: 190 | J417: 79.32 | K417: =TRIM(E417) -> Furniture | L417: =TEXT(B417,"mmm-yyyy") -> Jun-2025 | M417: =DATE(YEAR(B417),MONTH(B417),1) -> 45809
A418: ORD-00417 | B418: 45886 | C418: Customer 076 | D418: Keyboard | E418: Technology | F418: South | G418: 4 | H418: 0.15 | I418: 238 | J418: 46.44 | K418: =TRIM(E418) -> Technology | L418: =TEXT(B418,"mmm-yyyy") -> Aug-2025 | M418: =DATE(YEAR(B418),MONTH(B418),1) -> 45870
A419: ORD-00418 | B419: 45834 | C419: Customer 011 | D419: Laptop Pro 15 | E419: Technology | F419: North | G419: 4 | H419: 0 | I419: 4800 | J419: 1692.04 | K419: =TRIM(E419) -> Technology | L419: =TEXT(B419,"mmm-yyyy") -> Jun-2025 | M419: =DATE(YEAR(B419),MONTH(B419),1) -> 45809
A420: ORD-00419 | B420: 45730 | C420: Customer 027 | D420: Keyboard | E420: Technology | F420: West | G420: 3 | H420: 0.1 | I420: 189 | J420: 56.65 | K420: =TRIM(E420) -> Technology | L420: =TEXT(B420,"mmm-yyyy") -> Mar-2025 | M420: =DATE(YEAR(B420),MONTH(B420),1) -> 45717
A421: ORD-00420 | B421: 45836 | C421: Customer 058 | D421: Notebook Pack | E421: Office Supplies | F421: East | G421: 1 | H421: 0.15 | I421: 15.3 | J421: 3.24 | K421: =TRIM(E421) -> Office Supplies | L421: =TEXT(B421,"mmm-yyyy") -> Jun-2025 | M421: =DATE(YEAR(B421),MONTH(B421),1) -> 45809
A422: ORD-00421 | B422: 45692 | C422: Customer 044 | D422: Smartphone X | E422: Technology | F422: North | G422: 1 | H422: 0 | I422: 850 | J422: 376.16 | K422: =TRIM(E422) -> Technology | L422: =TEXT(B422,"mmm-yyyy") -> Feb-2025 | M422: =DATE(YEAR(B422),MONTH(B422),1) -> 45689
A423: ORD-00422 | B423: 46004 | C423: Customer 021 | D423: Office Chair | E423: Furniture | F423: East | G423: 2 | H423: 0.2 | I423: 448 | J423: 175.81 | K423: =TRIM(E423) -> Furniture | L423: =TEXT(B423,"mmm-yyyy") -> Dec-2025 | M423: =DATE(YEAR(B423),MONTH(B423),1) -> 45992
A424: ORD-00423 | B424: 45944 | C424: Customer 081 | D424: Bookshelf | E424: Furniture | F424: South | G424: 4 | H424: 0.05 | I424: 722 | J424: 134.83 | K424: =TRIM(E424) -> Furniture | L424: =TEXT(B424,"mmm-yyyy") -> Oct-2025 | M424: =DATE(YEAR(B424),MONTH(B424),1) -> 45931
A425: ORD-00424 | B425: 45753 | C425: Customer 079 | D425: Monitor 24 | E425: Technology | F425: South | G425: 4 | H425: 0.15 | I425: 1088 | J425: 479.12 | K425: =TRIM(E425) -> Technology | L425: =TEXT(B425,"mmm-yyyy") -> Apr-2025 | M425: =DATE(YEAR(B425),MONTH(B425),1) -> 45748
...

Sheet Analysis
B7: Metrics | C7: Values
B8: Total Sales | C8: =SUM('Clean Sales Data'!I:I) -> 787092.9
B9: Total Profit | C9: =SUM('Clean Sales Data'!J:J) -> 220965.28
B10: Total Quantity | C10: =SUM('Clean Sales Data'!G:G) -> 3060
B11: Profit Margin | C11: =C9/C8 -> 0.28073596
B14: Category Analysis | E14: Regional Performance
B15: Row Labels | C15: Sum of Sales | E15: Row Labels | F15: Sum of Sales | G15: Sum of Profit
B16: Furniture | C16: 158069.5 | E16: East | F16: 175969.65 | G16: 49281.13
B17: Office Supplies | C17: 67298.4 | E17: North | F17: 182652.6 | G17: 49657.91
B18: Technology | C18: 561725 | E18: South | F18: 200268.9 | G18: 59950.92
B19: Grand Total | C19: 787092.9 | E19: West | F19: 228201.75 | G19: 62075.32
E20: Grand Total | F20: 787092.9 | G20: 220965.28
B23: Profit by Product | E23: Monthly Sales & Profit
B24: Row Labels | C24: Sum of Profit | E24: Row Labels | F24: Sum of Sales | G24: Sum of Profit
B25: Laptop Pro 15 | C25: 67389.74 | E25: Jan | F25: 61244.3 | G25: 16352.99
B26: Smartphone X | C26: 58833.87 | E26: Feb | F26: 68517.45 | G26: 17988.48
B27: Monitor 24 | C27: 22520.16 | E27: Mar | F27: 55961.9 | G27: 16411.09
B28: Office Chair | C28: 17445.89 | E28: Apr | F28: 73609.7 | G28: 20339.52
B29: Printer | C29: 15762.93 | E29: May | F29: 66524.05 | G29: 17487.41
B30: Coffee Table | C30: 15542.21 | E30: Jun | F30: 77887.7 | G30: 23709.4
B31: Bookshelf | C31: 10117.32 | E31: Jul | F31: 55649.9 | G31: 17919.6
B32: Keyboard | C32: 4212.13 | E32: Aug | F32: 73392.9 | G32: 17997.04
B33: Desk Lamp | C33: 3536.03 | E33: Sept | F33: 53866.55 | G33: 15732.32
B34: Wireless Mouse | C34: 2643.7 | E34: Oct | F34: 61921.15 | G34: 19056.68
B35: Desk Organizer | C35: 1625.84 | E35: Nov | F35: 60570.25 | G35: 15784.68
B36: Notebook Pack | C36: 1335.46 | E36: Dec | F36: 77947.05 | G36: 22186.07
B37: Grand Total | C37: 220965.28 | E37: Grand Total | F37: 787092.9 | G37: 220965.28
B40: Product Profitability | E40: Product Sales & Profit Contribution
B41: Row Labels | C41: Sum of Margin Profit of Product | E41: Row Labels | F41: Sum of Sales | G41: Sum of Profit | H41: Profit Vs Sales Contribution
B42: Coffee Table | C42: 0.30406953 | E42: Bookshelf | F42: 0.045671864 | G42: 0.045786922 | H42: =G42-F42 -> 0.00011505767
B43: Notebook Pack | C43: 0.30400419 | E43: Coffee Table | F43: 0.064940238 | G43: 0.070337792 | H43: =G43-F43 -> 0.0053975548
B44: Desk Lamp | C44: 0.30176698 | E44: Desk Lamp | F44: 0.014887379 | G44: 0.01600265 | H44: =G44-F44 -> 0.0011152712
B45: Wireless Mouse | C45: 0.29385056 | E45: Desk Organizer | F45: 0.0074419424 | G45: 0.007357898 | H45: =G45-F45 -> -8.4044331e-05
B46: Office Chair | C46: 0.29355359 | E46: Keyboard | F46: 0.018347262 | G46: 0.019062407 | H46: =G46-F46 -> 0.00071514411
B47: Keyboard | C47: 0.29167855 | E47: Laptop Pro 15 | F47: 0.31803107 | G47: 0.30497886 | H47: =G47-F47 -> -0.01305221
B48: Smartphone X | C48: 0.28378974 | E48: Monitor 24 | F48: 0.10229034 | G48: 0.10191719 | H48: =G48-F48 -> -0.00037315148
B49: Bookshelf | C49: 0.2814432 | E49: Notebook Pack | F49: 0.0055811709 | G49: 0.0060437549 | H49: =G49 -F49 -> 0.00046258401
B50: Monitor 24 | C50: 0.27971184 | E50: Office Chair | F50: 0.0755057 | G50: 0.078953083 | H50: =G50-F50 -> 0.0034473831
B51: Desk Organizer | C51: 0.27756551 | E51: Printer | F51: 0.072479373 | G51: 0.071336682 | H51: =G51-F51 -> -0.0011426907
B52: Printer | C52: 0.27630995 | E52: Smartphone X | F52: 0.2633933 | G52: 0.26625844 | H52: =G52-F52 -> 0.002865132
...

Sheet Dashboard
E7: Total Sales | F7: Total Profit | G7: Total Quantity | H7: Profit Margin
E8: =Analysis!C8 -> 787092.9 | F8: =Analysis!C9 -> 220965.28 | G8: =Analysis!C10 -> 3060 | H8: =Analysis!C11 -> 0.28073596
